Workbook

Sheet 211
H1: RDSZ Building Room Information
A2: BUILDIN NO. | B2: BUILDING FLOOR | C2: Room-number | D2: ROOM NAME | E2: NET AREA | F2: FLOOR | G2: WALL | H2: CEILING | I2: CEILING HEIGHT | J2: SKIRTING FINISH | K2: Door | L2: Window | M2: HVAC | N2: FIRE FIGHTING | O2: NOTE NO.
A3: 楼号 | B3: 楼层 | C3: 房间号 | D3: 房间名称 | E3: 净面积(M2) | F3: 地面做法 | G3: 墙面做法 | H3: 吊顶做法 | I3: 吊顶高度 | J3: 踢脚作法 | K3: 门 | L3: 窗 | M3: 暖通 | N3: 消防 | O3: 备注索引
A4: 211 | B4: B1F 地下室 | C4: 001 | D4: 1#STAIRCASE 1#楼梯间 | E4: 18.8 | F4: F10环氧涂层地面 | G4: W1a丙烯酸乳胶漆涂料墙面(实体墙) | H4: C3丙烯酸乳胶漆涂料 | I4: N/A | J4: S3水泥砂浆踢脚 | L4: N/A
A5: 211 | B5: B1F 地下室 | C5: 002B | D5: HOT WATER RM 热水间 | E5: 82.6 | F5: F11a耐化学品、耐压、耐磨环氧自流平地面 | G5: W1a丙烯酸乳胶漆涂料墙面(实体墙) | H5: C2b防水石膏板吊顶 | I5: 贴梁底 | J5: S1环氧踢脚 | L5: N/A
A6: 211 | B6: B1F 地下室 | C6: 002A | D6: MECHANIC RM设备间 | E6: 84.3 | F6: F11a耐化学品、耐压、耐磨环氧自流平地面 | G6: W1a丙烯酸乳胶漆涂料墙面(实体墙) | H6: C3丙烯酸乳胶漆涂料 | I6: N/A | J6: S1环氧踢脚 | L6: N/A
A7: 211 | B7: B1F 地下室 | C7: 003 | D7: CORRIDOR走道 | E7: 173.6 | F7: F2b硬化剂地坪 | G7: W1a丙烯酸乳胶漆涂料墙面(实体墙) | H7: C3丙烯酸乳胶漆涂料 | I7: N/A | J7: S3水泥砂浆踢脚 | L7: N/A
A8: 211 | B8: B1F 地下室 | C8: 005 | D8: CORRIDOR走道 | E8: 151.3 | F8: F2b硬化剂地坪 | G8: W1a丙烯酸乳胶漆涂料墙面(实体墙) | H8: C3丙烯酸乳胶漆涂料 | I8: N/A | J8: S3水泥砂浆踢脚 | L8: N/A
A9: 211 | B9: B1F 地下室 | C9: 006 | D9: BREAK RM员工休息室 | E9: 17.8 | F9: F3乙烯基地面 | G9: W1a丙烯酸乳胶漆涂料墙面(实体墙) | H9: C1轻钢龙骨吸音板吊顶 | I9: 2200 | J9: S5乙烯基踢脚,2.5毫米厚 | L9: N/A
A10: 211 | B10: B1F 地下室 | C10: 007 | D10: WOMEN CHANGING RM女更衣室 | E10: 9.7 | F10: F3乙烯基地面 | G10: W1a丙烯酸乳胶漆涂料墙面(实体墙) | H10: C1轻钢龙骨吸音板吊顶 | I10: 2200 | J10: S5乙烯基踢脚,2.5毫米厚 | L10: N/A
A11: 211 | B11: B1F 地下室 | C11: 008 | D11: MEN CHANGING RM 男更衣室 | E11: 10.1 | F11: F3乙烯基地面 | G11: W1a丙烯酸乳胶漆涂料墙面(实体墙) | H11: C1轻钢龙骨吸音板吊顶 | I11: 2200 | J11: S5乙烯基踢脚,2.5毫米厚 | L11: N/A
A12: 211 | B12: B1F 地下室 | C12: 009 | D12: STORAGE RM一次性用品仓库 | E12: 10.5 | F12: F2b硬化剂地坪 | G12: W1a丙烯酸乳胶漆涂料墙面(实体墙) | H12: C2c 防火石膏板吊顶 | I12: 2200 | J12: S3水泥砂浆踢脚 | L12: N/A
A13: 211 | B13: B1F 地下室 | C13: 010 | D13: DESMOKE RM 2排烟机房2 | E13: 22.7 | F13: F2b硬化剂地坪 | G13: W1a丙烯酸乳胶漆涂料墙面(实体墙) | H13: C3丙烯酸乳胶漆涂料 | I13: N/A | J13: S3水泥砂浆踢脚 | L13: N/A
A14: 211 | B14: B1F 地下室 | C14: 011 | D14: 2#STAIRCASE 2#楼梯间 | E14: 18.8 | F14: F10环氧涂层地面 | G14: W1a丙烯酸乳胶漆涂料墙面(实体墙) | H14: C3丙烯酸乳胶漆涂料 | I14: N/A | J14: S3水泥砂浆踢脚 | L14: N/A
A15: 211 | B15: B1F 地下室 | C15: 012 | D15: WOMEN TOILET女卫 | E15: 14.3 | F15: F1a防滑陶瓷地砖 (有防水层） | G15: W2瓷砖墙面 | H15: C2b防水石膏板吊顶 | I15: 2800 | J15: N/A | L15: N/A
A16: 211 | B16: B1F 地下室 | C16: 012A | D16: WOMEN SHOWER女淋浴 | E16: 3.6 | F16: F1a | G16: W2瓷砖墙面 | H16: C2b防水石膏板吊顶 | I16: 2800 | J16: N/A | L16: N/A
A17: 211 | B17: B1F 地下室 | C17: 013 | D17: MEN TOILET男卫生间 | E17: 9.1 | F17: F1a | G17: W2瓷砖墙面 | H17: C5穿孔金属吸音吊顶 | I17: 3000 | J17: S2拉丝不锈钢踢脚 | L17: N/A
A18: 211 | B18: B1F 地下室 | C18: 013A | D18: MEN SHOWER男淋浴 | E18: 3.6 | F18: F1a | G18: W2瓷砖墙面 | H18: C5穿孔金属吸音吊顶 | I18: 2800 | J18: S2拉丝不锈钢踢脚 | L18: N/A
A19: 211 | B19: B1F 地下室 | C19: 015 | D19: FIRE FIGHTING POND 2消防水池2 | E19: 122.1 | F19: F9 | G19: W5 | H19: C7 | I19: N/A | J19: N/A | K19: N/A | L19: N/A
A20: 211 | B20: B1F 地下室 | C20: 016 | D20: FIRE FIGHTING POND 1消防水池1 | E20: 182.1 | F20: F9 | G20: W5 | H20: C7 | I20: N/A | J20: N/A | K20: N/A
A21: 211 | B21: B1F 地下室 | C21: 017 | D21: FUTURE EQUIPMENT RM预留设备间 | E21: 162.2 | F21: F11a | G21: W1a | H21: C3 | I21: N/A | J21: S3
A22: 211 | B22: B1F 地下室 | C22: 018 | D22: DESMOKE RM 1排烟机房 1 | E22: 28.6 | F22: F2b | G22: W1a | H22: C3 | I22: N/A | J22: S3
A23: 211 | B23: B1F 地下室 | C23: 019 | D23: LV SWITCH RM低压配电室 | E23: 65 | F23: F6 | G23: W1a | H23: C3 | I23: N/A | J23: S6
A24: 211 | B24: B1F 地下室 | C24: 019A | D24: UPS RMUPS间 | E24: 16.5 | F24: F6 | G24: W1a | H24: C3 | I24: N/A | J24: S3
A25: 211 | B25: B1F 地下室 | C25: 020 | D25: HVAC 1空调机房1 | E25: 44.9 | F25: F11a | G25: W1a | H25: C3 | I25: N/A | J25: N/A
A26: 211 | B26: B1F 地下室 | C26: 021 | D26: 7#ELEVATOR7#电梯 | E26: 6.4 | F26: N/A | G26: N/A | H26: N/A | I26: N/A | J26: S3
A27: 211 | B27: B1F 地下室 | C27: 022 | D27: FUTURE EQUIPMENT RM预留设备间 | E27: 36 | F27: F2b | G27: W1a | H27: C3 | I27: N/A | J27: S3
A28: 211 | B28: B1F 地下室 | C28: 023 | D28: ALARM VALVE报警阀间 | E28: 13.7 | F28: F2b | G28: W1a | H28: C3 | I28: N/A | J28: S3
A29: 211 | B29: B1F 地下室 | C29: 025 | D29: FIRE FIGHTING PUMP RM消防泵房 | E29: 388.8 | F29: F11a | G29: W1a | H29: C3 | I29: N/A | J29: S3
A30: 211 | B30: B1F 地下室 | C30: 027 | D30: HVAC RM 2空调机房2 | E30: 105.3 | F30: F11a | G30: W1a | H30: C3 | I30: N/A | J30: S3
A31: 211 | B31: B1F 地下室 | D31: 单层建筑面积 | E31: 2042.9
A32: 211 | B32: 1F 一层 | C32: 101 | D32: 1#STAIRCASE1#楼梯间 | E32: 17.2 | F32: F10/F4 | G32: W1a | H32: C3 | I32: N/A | J32: S3/S4
A33: 211 | B33: 1F 一层 | C33: 102 | D33: CORRIDOR走道 | E33: 10.8 | F33: F4 | G33: W2瓷砖墙面 | H33: C5穿孔金属吸音吊顶 | I33: 2800 | J33: S2
A34: 211 | B34: 1F 一层 | C34: 102A | D34: HANDICAPPED'S RM无障碍卫生间 | E34: 6.4 | F34: F1b | G34: W2瓷砖墙面 | H34: C2b防水石膏板吊顶 | I34: 2800 | J34: N/A
A35: 211 | B35: 1F 一层 | C35: 103 | D35: WOMEN TOILET女卫生间 | E35: 13.4 | F35: F1b | G35: W2瓷砖墙面 | H35: C2b防水石膏板吊顶 | I35: 2800 | J35: N/A
A36: 211 | B36: 1F 一层 | C36: 105 | D36: TOILET LOBBY厕所前室 | E36: 18.6 | F36: F1b | G36: W2瓷砖墙面 | H36: C2b防水石膏板吊顶 | I36: 2800 | J36: N/A
A37: 211 | B37: 1F 一层 | C37: 106 | D37: MEN TOILET男卫生间 | E37: 17.2 | F37: F1b | G37: W2瓷砖墙面 | H37: C2b防水石膏板吊顶 | I37: 2800 | J37: N/A
A38: 211 | B38: 1F 一层 | C38: 107 | D38: LOBBY 1门厅1 | E38: 335 | F38: F4 | G38: W1 | H38: C5穿孔金属吸音吊顶 | I38: 3700 | J38: S2拉丝不锈钢踢脚
A39: 211 | B39: 1F 一层 | C39: 107A | D39: LOBBY 2门厅2 | E39: 5.3 | F39: F4 | G39: W1 | H39: C5穿孔金属吸音吊顶 | I39: 3700 | J39: S2拉丝不锈钢踢脚
A40: 211 | B40: 1F 一层 | C40: 108 | D40: CANTEEN餐厅 | E40: 722 | F40: F4 | G40: W1 | H40: C5穿孔金属吸音吊顶 | I40: 3700 | J40: S2拉丝不锈钢踢脚
...

Sheet 113
H1: ='211'!H1 -> RDSZ Building Room Information
A2: ='211'!A2 -> BUILDIN NO. | B2: ='211'!B2 -> BUILDING FLOOR | C2: ='211'!C2 -> Room-number | D2: ='211'!D2 -> ROOM NAME | E2: ='211'!E2 -> NET AREA | F2: ='211'!F2 -> FLOOR | G2: ='211'!G2 -> WALL | H2: ='211'!H2 -> CEILING | ... O2: ='211'!O2 -> NOTE NO.
A3: ='211'!A3 -> 楼号 | B3: ='211'!B3 -> 楼层 | C3: ='211'!C3 -> 房间号 | D3: ='211'!D3 -> 房间名称 | E3: ='211'!E3 -> 净面积(M2) | F3: ='211'!F3 -> 地面做法 | G3: ='211'!G3 -> 墙面做法 | H3: ='211'!H3 -> 吊顶做法 | ... O3: ='211'!O3 -> 备注索引
A4: 113 | B4: 1F 一层 | C4: 101 | D4: 楼梯间一（东） Staircase1（East） | E4: 19.5 | F4: F3 | G4: W1 | H4: C4 | I4: N/A | J4: S4
A5: 113 | B5: 1F 一层 | C5: 102 | D5: 走道CORRIDOR | E5: 24.5 | F5: F8 | G5: W1 | H5: C6 | I5: 2800 | J5: S1
A6: 113 | B6: 1F 一层 | C6: 103 | D6: 废水站化学品存储间 WWT Chemical Storage RM | E6: 12.1 | F6: F8 | G6: W1 | H6: N/A | I6: N/A | J6: S1
A7: 113 | B7: 1F 一层 | C7: 105 | D7: 耗材备品间Supplies Storage room | E7: 51.9 | F7: F8 | G7: W1 | H7: N/A | I7: N/A | J7: S1
A8: 113 | B8: 1F 一层 | C8: 106 | D8: 废弃物暂存WASTE STORAGE | E8: 41.4 | F8: F8 | G8: W1 | H8: N/A | I8: N/A | J8: S1
A9: 113 | B9: 1F 一层 | C9: 109 | D9: UPS RM 1 UPS室1 | E9: 11.2 | F9: F9 | G9: W1 | H9: N/A | I9: N/A | J9: S6
A10: 113 | B10: 1F 一层 | C10: 112 | D10: LV SWITCH RM开关室 | E10: 189.2 | F10: F9 | G10: W1 | H10: N/A | I10: N/A | J10: S6
A11: 113 | B11: 1F 一层 | C11: 113 | D11: 消防及安保监控室SECURITY CENTER | E11: 81.1 10.5M2 22.7M2 | F11: F9 | G11: W1 | H11: C1 | I11: 3100 | J11: S6
A12: 113 | B12: 1F 一层 | C12: 115 | D12: 女更衣室 Female Gowning MEN GOWNING男更衣 | E12: 8.9 22.7M2 | F12: F5 | G12: W1 | H12: C1 | I12: 2800 | J12: S2
A13: 113 | B13: 1F 一层 | C13: 116 | D13: 男更衣室 Male Gowning | E13: 9.2 | F13: F5 | G13: W1 | H13: C1 | I13: 2800 | J13: S2
A14: 113 | B14: 1F 一层 | C14: 117 | D14: UPS室3 UPS Room 3 | E14: 24.6 | F14: F8 | G14: W1 | H14: C1 | I14: 3000 | J14: S1
A15: 113 | B15: 1F 一层 | C15: 118 | D15: 管道井SHAFT | E15: 8.3 | F15: N/A | G15: W1 | H15: N/A | I15: N/A | J15: N/A
A16: 113 | B16: 1F 一层 | C16: 119 | D16: 休息室BREAK RM | E16: 38 | F16: F5 | G16: W1 | H16: C1 | I16: 3000 | J16: S2
A17: 113 | B17: 1F 一层 | C17: 120 | D17: 本地应急指挥响应中心 LEM RM | E17: 64 | F17: F6 | G17: W1 | H17: C1 | I17: 3000 | J17: S2
A18: 113 | B18: 1F 一层 | C18: 121 | D18: CORRIDOR走道 | E18: 30.86 | F18: F8 | G18: W1 | H18: C6 | I18: 2800 | J18: S1
A19: 113 | B19: 1F 一层 | C19: 122 | D19: 楼梯间二（西南） Staircase 2 (South-West) | E19: 19.2 | F19: F3 | G19: W1 | H19: C4 | I19: N/A | J19: S4
A20: 113 | B20: 1F 一层 | C20: 123 | D20: 9#电梯 9#Elevator | E20: 8.3 | F20: N/A | G20: N/A | H20: N/A | I20: N/A | J20: N/A
A21: 113 | B21: 1F 一层 | C21: 126 | D21: 门厅LOBBY | E21: 12.5 | F21: F3 | G21: W1 | H21: C6 | I21: 2800 | J21: S2
A22: 113 | B22: 1F 一层 | C22: 127 | D22: 楼梯间三（西北） Staircase 3 (North-West) | E22: 112.8 | F22: F3 | G22: W1 | H22: C6 | I22: N/A | J22: N/A
A23: 113 | B23: 1F 一层 | C23: 128 | D23: FUTURE OFFICE预留办公室 | E23: 64.6 | F23: F6 | G23: W1 | H23: C1 | I23: 3000 | J23: S2
A24: 113 | B24: 1F 一层 | C24: 130a | D24: 心理咨询室 Psychological Counseling Room | E24: 8.9 | F24: F6 | G24: W1 | H24: C1 | I24: 3000 | J24: S2
A25: 113 | B25: 1F 一层 | C25: 130b | D25: 理疗室Physical Therapy Room | E25: 13.5 | F25: F6 | G25: W1 | H25: C1 | I25: 3000 | J25: S2
A26: 113 | B26: 1F 一层 | C26: 131 | D26: PANTRY茶水间 | E26: 7.9 | F26: F5 | G26: W1 | H26: C1 | I26: 2800 | J26: S2
A27: 113 | B27: 1F 一层 | C27: 132 | D27: 洁具间 Janitor Room | E27: 5.3 | F27: F2 | G27: W2 | H27: C5 | I27: 2800 | J27: N/A
A28: 113 | B28: 1F 一层 | C28: 133 | D28: 司机休息室 Driver | E28: 53.3 | F28: F6 | G28: W1 | H28: C1 | I28: 3000 | J28: S2
A29: 113 | B29: 1F 一层 | C29: 135 | D29: 阀组间 Sprinkler Room | E29: 7.3 | F29: F10 | G29: W1 | H29: N/A | I29: N/A | J29: S3
A30: 113 | B30: 1F 一层 | C30: 136 | D30: 储藏间 Storage RM | E30: 41.2 | F30: F5 | G30: W1 | H30: C1 | I30: 3000 | J30: S2
A31: 113 | B31: 1F 一层 | C31: 137 | D31: 样品间Sample Room | E31: 86.9 | F31: F6 | G31: W1 | H31: C1 | I31: 3000 | J31: S2
A32: 113 | B32: 1F 一层 | C32: 138 | D32: 走道CORRIDOR | E32: 143.2 | F32: F5 | G32: W1 | H32: C6 | I32: 2800 | J32: S2
A33: 113 | B33: 1F 一层 | C33: 139 | D33: 走道CORRIDOR | E33: 22.4 | F33: F8 | G33: W1 | H33: C6 | I33: 2800 | J33: S1
A34: 113 | B34: 1F 一层 | C34: 150 | D34: 管道井SHAFT | E34: 14.4
A35: 113 | B35: 1F 一层 | C35: 151 | D35: 10#电梯 10#Elevator | E35: 9.9 | F35: N/A | G35: N/A | H35: N/A | I35: N/A | J35: N/A
A36: 113 | B36: 1F 一层 | C36: 152 | D36: 档案室ARCHIVE | E36: 118.1 | F36: F5 | G36: W1 | H36: C1 | I36: 2900 | J36: S1
A37: 113 | B37: 1F 一层 | C37: 153 | D37: 空调机房 HVAC Room | E37: 43.6 | F37: F10 | G37: W1 | H37: N/A | I37: N/A | J37: S3
A38: 113 | B38: 1F 一层 | C38: 155 | D38: IT操作室 IT OPERATION RM | E38: 15.4 | F38: F10 | G38: W1 | H38: N/A | I38: 2900 | J38: S3
A39: 113 | B39: 1F 一层 | C39: 155A | D39: DATA Center 数据中心 | E39: 59.4 | F39: F10 | G39: W1 | H39: N/A | I39: 2900 | J39: S3
A40: 113 | B40: 1F 一层 | C40: 156 | D40: IG541室 IG541 Room | E40: 9.6 | F40: F8 | G40: W1 | H40: C4 | I40: 2900 | J40: S1
...

Sheet 121
H1: ='211'!H1 -> RDSZ Building Room Information
A2: ='211'!A2 -> BUILDIN NO. | B2: ='211'!B2 -> BUILDING FLOOR | C2: ='211'!C2 -> Room-number | D2: ='211'!D2 -> ROOM NAME | E2: ='211'!E2 -> NET AREA | F2: ='211'!F2 -> FLOOR | G2: ='211'!G2 -> WALL | H2: ='211'!H2 -> CEILING | ... O2: ='211'!O2 -> NOTE NO.
A3: ='211'!A3 -> 楼号 | B3: ='211'!B3 -> 楼层 | C3: ='211'!C3 -> 房间号 | D3: ='211'!D3 -> 房间名称 | E3: ='211'!E3 -> 净面积(M2) | F3: ='211'!F3 -> 地面做法 | G3: ='211'!G3 -> 墙面做法 | H3: ='211'!H3 -> 吊顶做法 | ... O3: ='211'!O3 -> 备注索引
A4: 121 | B4: 1F 一层 | C4: 101 | D4: 楼梯间二（北） Staircase 2 (North) | E4: 31 | F4: F17环氧涂层地面 | G4: W3 | H4: C4 | I4: N/A | J4: S8 | M4: 冷梁，空调机，风机盘管，排风，送风机，排烟，热交换器，正压送风，高效过滤器，旅行。
A5: 121 | B5: 1F 一层 | C5: 102 | D5: 走道 Corridor | E5: 89.5 | F5: F8a环氧自流平地面（有防水层） | G5: W3 | H5: C3 | I5: N/A | J5: S1环氧踢脚
A6: 121 | B6: 1F 一层 | C6: 105 | D6: 污水处理 Waste Water Treatment | E6: 134.8 | F6: F8a环氧自流平地面（有防水层） | G6: W3 | H6: N/A | I6: N/A | J6: S1环氧踢脚
A7: 121 | B7: 1F 一层 | C7: 106 | D7: 纯蒸汽锅炉房 Clean Steam Boiler | E7: 47.6 | F7: F8a环氧自流平地面（有防水层） | G7: W1 | H7: C1 | I7: N/A | J7: S3环氧涂层踢脚
A8: 121 | B8: 1F 一层 | C8: 107 | D8: 预留Reserved | E8: 106.9 | F8: F8a环氧自流平地面（有防水层） | G8: W1 | H8: C1 | I8: N/A | J8: S3环氧涂层踢脚
A9: 121 | B9: 1F 一层 | C9: 108 | D9: 预留Reserved | E9: 38.4 | F9: F8a | G9: W1 | H9: C1 | I9: 3200 | J9: S5乙烯基踢脚,2.5毫米厚
A10: 121 | B10: 1F 一层 | C10: 109 | D10: 灌装间Filling | E10: 296.6 | F10: F8a | G10: W1 | H10: C1 | I10: 3200 | J10: S5乙烯基踢脚,2.5毫米厚
A11: 121 | B11: 1F 一层 | C11: 110 | D11: 洁具间 Janitor | E11: 19.7 | F11: F8a | G11: W3 | H11: C1 | I11: 3200 | J11: S1环氧踢脚
A12: 121 | B12: 1F 一层 | C12: 111 | D12: 工作间 Workshop | E12: 17.4 | F12: F8a | G12: W3 | H12: C1 | I12: N/A | J12: S1环氧踢脚
A13: 121 | B13: 1F 一层 | C13: 112 | D13: 标签打印间 Label Printing Room | E13: 181.1 | F13: F8a | G13: W3 | H13: C1 | I13: N/A | J13: S1环氧踢脚
A14: 121 | B14: 1F 一层 | C14: 113 | D14: 楼梯间一（南） Staircase 1 (South) | E14: 37 | F14: F17环氧涂层地面 | G14: W1a丙烯酸乳胶漆涂料墙面 | H14: C5穿孔金属吸音吊顶 | I14: 3000 | J14: S1环氧踢脚
A15: 121 | B15: 1F 一层 | C15: 115 | D15: 包材存储间 Packaging Material Storage Room | E15: 137 | F15: F8a | G15: W1b/W3b丙烯酸乳胶漆涂料墙面(轻质隔墙)9M2/无框玻璃隔断35.3M2 | H15: C5穿孔金属吸音吊顶 | I15: 2800 | J15: S2
A16: 121 | B16: 1F 一层 | C16: 115A | D16: 管井 Pipe Shaft | E16: 7.2 | F16: N/A | G16: N/A | H16: N/A | I16: N/A | J16: N/A
A17: 121 | B17: 1F 一层 | C17: 116 | D17: 备用楼梯间 Future Staircase | E17: 40.4 | F17: F8 | G17: W1 | H17: N/A | I17: N/A | J17: S1环氧踢脚
A18: 121 | B18: 1F 一层 | C18: 118 | D18: 走道 Corridor | E18: 725.4 | F18: F8a | G18: W1a/W1b | H18: C1b/C2 | I18: 3200 | J18: S1环氧踢脚
A19: 121 | B19: 1F 一层 | C19: 119 | D19: 校准品灌装CNC Calibrator Filling CNC | E19: 59.2 | F19: F2耐化学品，耐压，耐磨环氧自流平地面 | G19: W1 | H19: C1 | I19: 3200 | J19: S5乙烯基踢脚,2.5毫米厚
A20: 121 | B20: 1F 一层 | C20: 120 | D20: 校准品灌装 Calibrator Filling | E20: 78.4 | F20: F2 | G20: W1 | H20: C1 | I20: 3200 | J20: S5乙烯基踢脚,2.5毫米厚
A21: 121 | B21: 1F 一层 | C21: 121 | D21: 配制 Compounding | E21: 39.4 | F21: F2 | G21: W1 | H21: C1 | I21: 3200 | J21: S5乙烯基踢脚,2.5毫米厚
A22: 121 | B22: 1F 一层 | C22: 122 | D22: 洁具间 Janitor | E22: 4.7 | F22: F2 | G22: W1 | H22: C1 | I22: 3200 | J22: S5乙烯基踢脚,2.5毫米厚
A23: 121 | B23: 1F 一层 | C23: 123 | D23: 中间品储存 WIP Storage | E23: 19.4 | F23: F2 | G23: W1 | H23: C1 | I23: 3200 | J23: S5乙烯基踢脚,2.5毫米厚
A24: 121 | B24: 1F 一层 | C24: 125 | D24: 走道 Corridor | E24: 95.7 | F24: F2 | G24: W1 | H24: C1 | I24: 3200 | J24: S5乙烯基踢脚,2.5毫米厚
A25: 121 | B25: 1F 一层 | C25: 126 | D25: 在线清洗站 CIP Skid | E25: 23.7 | F25: F2 | G25: W1 | H25: C1 | I25: 3200 | J25: S5乙烯基踢脚,2.5毫米厚
A26: 121 | B26: 1F 一层 | C26: 127 | D26: 支持间 Support Room | E26: 11 | F26: F2 | G26: W1 | H26: C1 | I26: 3200 | J26: S5乙烯基踢脚,2.5毫米厚
A27: 121 | B27: 1F 一层 | C27: 128 | D27: 清洗间Cleaning Area | E27: 32.4 | F27: F2 | G27: W1 | H27: C1 | I27: 3200 | J27: S5乙烯基踢脚,2.5毫米厚
A28: 121 | B28: 1F 一层 | C28: 129 | D28: 人员缓冲间 PAL | E28: 5.5 | F28: F2 | G28: W1 | H28: C1 | I28: 3200 | J28: S5乙烯基踢脚,2.5毫米厚
A29: 121 | B29: 1F 一层 | C29: 130 | D29: 更衣 Gowning | E29: 9.8 | F29: F2 | G29: W1 | H29: C1 | I29: 3200 | J29: S5乙烯基踢脚,2.5毫米厚
... A32: 121 | B32: 1F 一层 | C32: 135 | D32: 中控室 IPC | E32: 22.3 | F32: F2 | G32: W1 | H32: C1 | I32: 3200 | J32: S5乙烯基踢脚,2.5毫米厚
A33: 121 | B33: 1F 一层 | C33: 136 | D33: 备料间 Material Staging | G33: W1 | H33: C1 | I33: 3200 | J33: S5乙烯基踢脚,2.5毫米厚
A34: 121 | B34: 1F 一层 | C34: 137 | D34: 免疫灌装 Elecsys Filling | E34: 132.6 | F34: F2 | G34: W1 | H34: C1 | I34: 3200 | J34: S5乙烯基踢脚,2.5毫米厚
A35: 121 | B35: 1F 一层 | C35: 138 | D35: 包装车间Packaging Hall | E35: 2065.7 | F35: F8a | G35: W1a | H35: C1/C3 | I35: 3200 | J35: S1环氧踢脚
A36: 121 | B36: 1F 一层 | C36: 139 | D36: 物料缓冲间 MAL | E36: 3.6 | F36: F2 | G36: W1 | H36: C1 | I36: 3200 | J36: S5乙烯基踢脚,2.5毫米厚
A37: 121 | B37: 1F 一层 | C37: 140 | D37: 清洁/消毒 2 COP/SOP 2 | E37: 9.3 | F37: F2 | G37: W1 | H37: C1 | I37: 3200 | J37: S5乙烯基踢脚,2.5毫米厚
A38: 121 | B38: 1F 一层 | C38: 141 | D38: 清洁/ 消毒1 COP SOP 1 | E38: 9.1 | F38: F2 | G38: W1 | H38: C1 | I38: 3200 | J38: S5乙烯基踢脚,2.5毫米厚
A39: 121 | B39: 1F 一层 | C39: 142 | D39: 灌装间 Filling Room | E39: 15.2 | F39: F2 | G39: W1 | H39: C1 | I39: 3200 | J39: S5乙烯基踢脚,2.5毫米厚
A40: 121 | B40: 1F 一层 | C40: 143 | D40: 消毒 SOP | E40: 9.3 | F40: F2 | G40: W1 | H40: C1 | I40: 3200 | J40: S5乙烯基踢脚,2.5毫米厚
A41: 121 | B41: 1F 一层 | C41: 145 | D41: 清洗/消毒间 COP/SOP | E41: 9.1 | F41: F2 | G41: W1 | H41: C1 | I41: 3200 | J41: S5乙烯基踢脚,2.5毫米厚
A42: 121 | B42: 1F 一层 | C42: 150 | D42: 物料缓冲间 MAL | E42: 3.6 | F42: F2 | G42: W1 | H42: C1 | I42: 3200 | J42: S5乙烯基踢脚,2.5毫米厚
...

Sheet 231
H1: ='211'!H1 -> RDSZ Building Room Information
A2: ='211'!A2 -> BUILDIN NO. | B2: ='211'!B2 -> BUILDING FLOOR | C2: ='211'!C2 -> Room-number | D2: ='211'!D2 -> ROOM NAME | E2: ='211'!E2 -> NET AREA | F2: ='211'!F2 -> FLOOR | G2: ='211'!G2 -> WALL | H2: ='211'!H2 -> CEILING | ... O2: ='211'!O2 -> NOTE NO.
A3: ='211'!A3 -> 楼号 | B3: ='211'!B3 -> 楼层 | C3: ='211'!C3 -> 房间号 | D3: ='211'!D3 -> 房间名称 | E3: ='211'!E3 -> 净面积(M2) | F3: ='211'!F3 -> 地面做法 | G3: ='211'!G3 -> 墙面做法 | H3: ='211'!H3 -> 吊顶做法 | ... O3: ='211'!O3 -> 备注索引
A4: 231 | B4: 1F | C4: 101 | D4: 楼梯间三（东北） Staircase 3 (North-East) | E4: 22.2 | F4: F17环氧涂层地面 | G4: W1a | H4: C4 | I4: N/A | J4: S8
A5: 231 | B5: 1F | C5: 102 | D5: 洁具间 Janitor | E5: 9.4 | F5: F2 | G5: W1b | H5: C5 | I5: 2700 | J5: S6
A6: 231 | B6: 1F | C6: 103 | D6: 设备间 Technical Room | E6: 16.7 | F6: F5 | G6: W5 | H6: C4 | I6: N/A | J6: S6
A7: 231 | B7: 1F | C7: 105 | D7: 管井 Pipe Shaft | E7: 3 | F7: N/A | G7: N/A | H7: N/A | I7: N/A | J7: N/A
A8: 231 | B8: 1F | C8: 106 | D8: 取样室 Sampling Room | E8: 26.3 | F8: F1 | G8: W3 | H8: C3 | I8: 2800 | J8: S1
A9: 231 | B9: 1F | C9: 107 | D9: 人员前室 PAL | E9: 4.2 | F9: F1 | G9: W3 | H9: C3 | I9: 2800 | J9: S1
A10: 231 | B10: 1F | C10: 108 | D10: 物料气闸室 Material Airlock | E10: 6.5 | F10: F1 | G10: W3 | H10: C3 | I10: 2800 | J10: S1
A11: 231 | B11: 1F | C11: 109 | D11: 更衣室 Gowning | E11: 12 | F11: F1 | G11: W3 | H11: C3 | I11: 2800 | J11: S1
A12: 231 | B12: 1F | C12: 110 | D12: 废物存放 Waste Storage | E12: 36 | F12: F1 | G12: W1b | H12: C4 | I12: N/A | J12: S1
A13: 231 | B13: 1F | C13: 111 | D13: 包材检验室2 packaging material inspection room2 | E13: 22.3 | F13: F1 | G13: W1a | H13: C4 | I13: N/A | J13: S1
A14: 231 | B14: 1F | C14: 112 | D14: 楼梯间四（东南） Staircase 4 (South-East) | E14: 23.6 | F14: F17环氧涂层地面 | G14: W1a | H14: C4 | I14: N/A | J14: S8
A15: 231 | B15: 1F | C15: 113 | D15: 驾驶员休息室 Driver Room | E15: 6.8 | F15: F5 | G15: W1a | H15: C1 | I15: 2800 | J15: S6
A16: 231 | B16: 1F | C16: 113A | D16: 卫生间 Toilet | E16: 4.1 | F16: F2 | G16: W2 | H16: C5 | I16: 2700 | J16: N/A
A17: 231 | B17: 1F | C17: 115 | D17: 收发室 Reception | E17: 21.9 | F17: F6 | G17: S6 | H17: W1a | I17: 2800 | J17: S6
A18: 231 | B18: 1F | C18: 116 | D18: 物料缓冲间 Material Buffer | E18: 15.4 | F18: F1 | G18: W1a | H18: C4 | I18: 3000 | J18: S1
A19: 231 | B19: 1F | C19: 117 | D19: 物料缓冲间 Material Buffer | E19: 15.4 | F19: F1 | G19: W1a | H19: C4 | I19: 3000 | J19: S1
A20: 231 | B20: 1F | C20: 118 | D20: 物料缓冲间 Material Buffer | E20: 14.7 | F20: F1 | G20: W1a | H20: C4 | I20: 3000 | J20: S1
A21: 231 | B21: 1F | C21: 119 | D21: 物料缓冲间（冷库） Material Buffer（Cold Room） | E21: 14.1 | F21: F1 | G21: W1a | H21: C6 | I21: 3000 | J21: S1
A22: 231 | B22: 1F | C22: 125 | D22: 高架冷库 High Bay Cold Room Storage | E22: 1089.3
A23: 231 | B23: 1F | C23: 126 | D23: 高架冷库 High Bay Cold Room Storage | E23: 1071.2
A24: 231 | B24: 1F | C24: 127 | D24: 室温高架库 High Bay Room Temperature Storage | E24: 1088.1 | F24: F1 | G24: W4 | H24: C4 | I24: N/A | J24: S1
A25: 231 | B25: 1F | C25: 128 | D25: 堆存区（丙类2项） Block Storage (Class C2) | E25: 841 | F25: F1 | G25: W1a | H25: C4 | I25: N/A | J25: S1
A26: 231 | B26: 1F | C26: 129 | D26: 楼梯间一（西北） Staircase 1 (North-West) | E26: 27.9 | F26: F17环氧涂层地面 | G26: W1a/W1b | H26: C2 | I26: N/A | J26: S8
A27: 231 | B27: 1F | C27: 130 | D27: 消防阀室 Sprinkler Valve Room | E27: 19.5 | F27: F1 | G27: W1a | H27: C4 | I27: N/A | J27: S1
A28: 231 | B28: 1F | C28: 131 | D28: 走道 Corridor | E28: 9.6 | F28: F1 | G28: W1a | H28: C4 | I28: N/A | J28: S1
A29: 231 | B29: 1F | C29: 132 | D29: 楼梯间二（北） Staircase 2 (North) | E29: 27.9 | F29: F17环氧涂层地面 | G29: W1a | H29: C4 | I29: N/A | J29: S8
A30: 231 | B30: 1F | C30: 133 | D30: 走道 Corridor128 | E30: 79.3 | F30: F1 | G30: W1 | H30: C4 | I30: N/A | J30: S1
A31: 231 | B31: 1F | C31: 135 | D31: 1F-2#电梯 1F-2#Elevator | E31: 7.8 | F31: N/A | G31: N/A | H31: N/A | I31: N/A | J31: N/A
A32: 231 | B32: 1F | C32: 136 | D32: 1F-3#电梯 1F-3#Elevator | E32: 10.5 | F32: N/A | G32: N/A | H32: N/A | I32: N/A | J32: N/A
A33: 231 | B33: 1F | C33: 137 | D33: 办公室 Office | E33: 20.5 | F33: F1 | G33: W1 | H33: C4 | I33: N/A | J33: S1
A34: 231 | B34: 1F | C34: 138 | D34: 收发区 Shipping and Receiving | E34: 857.7 | F34: F1 | G34: W1a/W1b | H34: C4 | I34: N/A | J34: S1
A35: 231 | B35: 1F | C35: 139 | D35: 预冷室 Pre Cooling Room | E35: 115.1
A36: 231 | B36: 1F | C36: 150 | D36: 走道 Corridor | E36: 109.2 | F36: F1 | G36: W1 | H36: C1 | I36: N/A | J36: S1
A37: 231 | B37: 1F | C37: 160 | D37: 缓冲间 Buffer
A38: 113 | B38: 1F 一层 | D38: 单层建筑面积 | E38: 6005.6
A39: 231 | B39: 2F | C39: 201 | D39: 楼梯间三（东北） Staircase 3 (North-East) | E39: 22.2 | F39: F17环氧涂层地面 | G39: W1a/w1b | H39: C4 | I39: N/A | J39: S8
A40: 231 | B40: 2F | C40: 202 | D40: 男卫 Male Toilet | E40: 14.4 | F40: F2 | G40: W2a | H40: C5 | I40: 2700 | J40: N/A
...

Sheet 232
H1: ='211'!H1 -> RDSZ Building Room Information
A2: ='211'!A2 -> BUILDIN NO. | B2: ='211'!B2 -> BUILDING FLOOR | C2: ='211'!C2 -> Room-number | D2: ='211'!D2 -> ROOM NAME | E2: ='211'!E2 -> NET AREA | F2: ='211'!F2 -> FLOOR | G2: ='211'!G2 -> WALL | H2: ='211'!H2 -> CEILING | ... O2: ='211'!O2 -> NOTE NO.
A3: ='211'!A3 -> 楼号 | B3: ='211'!B3 -> 楼层 | C3: ='211'!C3 -> 房间号 | D3: ='211'!D3 -> 房间名称 | E3: ='211'!E3 -> 净面积(M2) | F3: ='211'!F3 -> 地面做法 | G3: ='211'!G3 -> 墙面做法 | H3: ='211'!H3 -> 吊顶做法 | ... O3: ='211'!O3 -> 备注索引
A4: 231 | B4: BF | C4: N/A | D4: 水池 Pound | E4: N/A | F4: N/A | G4: N/A | H4: N/A | I4: N/A | J4: N/A
A5: 232 | B5: 1F | C5: 101 | D5: 楼梯间 Staircase | E5: 19.2 | F5: F17 | G5: W1a | H5: C4 | I5: N/A | J5: S1
A6: 232 | B6: 1F | C6: 102 | D6: 配电室 ELEC Room | E6: 142.3 | F6: F9 | G6: W1a | H6: C4 | I6: N/A | J6: S6
A7: 232 | B7: 1F | C7: 103 | D7: UPS室 UPS Room | E7: 12.9 | F7: F9 | G7: W1a | H7: C4 | I7: N/A | J7: S6
A8: 232 | B8: 1F | C8: 105 | D8: 楼梯间 Staircase | E8: 19.2 | F8: F17 | G8: W1a | H8: C4 | I8: N/A | J8: S1
A9: 232 | B9: 1F | C9: 106 | D9: 洗涤塔间 Scrubber | E9: 13 | F9: F10c | G9: W1b | H9: C8 | I9: N/A | J9: S1
A10: 232 | B10: 1F | C10: 107 | D10: 冷冻机房 Chiller Room | E10: 30.9 | F10: F10c | G10: W1b | H10: C3 | I10: 5000 | J10: N/A
A11: 232 | B11: 1F | C11: 108 | D11: 冷冻机房 Chiller Room | E11: 32.2 | F11: F10c | G11: W7 | H11: C3 | I11: 5000 | J11: N/A
A12: 232 | B12: 1F | C12: 109 | D12: 冷冻机房 Chiller Room | E12: 61.6 | F12: F10c | G12: W7 | H12: C3 | I12: 6400 | J12: N/A
A13: 232 | B13: 1F | C13: 110 | D13: 冷冻机房 Chiller Room | E13: 58.1 | F13: F10c | G13: W7 | H13: C3 | I13: 6400 | J13: N/A
A14: 232 | B14: 1F | C14: 111 | D14: 冷冻机房 Chiller Room | E14: 58.1 | F14: F10c | G14: W7 | H14: C3 | I14: 6400 | J14: N/A
A15: 232 | B15: 1F | C15: 112 | D15: 泵房 Pump Room | E15: 59.6 | F15: F10c | G15: W7 | H15: C8 | I15: N/A | J15: N/A
A16: 232 | B16: 1F | C16: 113 | D16: 走道 Corridor | E16: 99.5 | F16: F10c | G16: W7 | H16: C8 | I16: N/A | J16: S3
A17: 232 | B17: 1F | C17: 115 | D17: 前室 Lobby | E17: 16.7 | F17: F1 | G17: W1a | H17: C4 | I17: N/A | J17: S1
A18: 232 | B18: 1F | C18: 116 | D18: 设备间 Mechanical Room | E18: 272.2 | F18: F1 | G18: W1a | H18: C4 | I18: N/A | J18: S1
A19: 232 | B19: 1F | C19: 117 | D19: 电梯间Elevator | E19: 8.3 | F19: N/A | G19: N/A | H19: N/A | I19: N/A | J19: N/A
A20: 232 | B20: 1F | C20: 118 | D20: 前室 Lobby | E20: 29.8 | F20: F1 | G20: W1a | H20: C4 | I20: N/A | J20: N/A
A21: 232 | B21: 1F | C21: 119 | D21: 泵房 Pump Room | E21: 20.6 | F21: F10c | G21: W7 | H21: C8 | I21: N/A | J21: N/A
A22: 232 | B22: 1F | D22: 单层建筑面积 | E22: 1042.5
A23: 232 | B23: 2F | C23: 201 | D23: 楼梯间 Staircase | E23: 23.1 | F23: F17 | G23: W1a | H23: C4 | I23: N/A | J23: S1
A24: 232 | B24: 2F | C24: 202 | D24: 弱电间 MDF&IDF Room | E24: 21.6 | F24: F9 | G24: W1a | H24: C1 | I24: 3000 | J24: S6
A25: 232 | B25: 2F | C25: 203 | D25: 空调机房 HVAC Room | E25: 132.3 | F25: F1 | G25: W1a | H25: C4 | I25: N/A | J25: S1
A26: 232 | B26: 2F | C26: 203(A) | D26: 管道井 Shaft | E26: 4 | F26: F9 | G26: W1a | H26: C4 | I26: N/A | J26: S2
A27: 232 | B27: 2F | C27: 205 | D27: 机柜室 Cabinet Room | E27: 46.2 | F27: F9 | G27: W1a | H27: C4 | I27: N/A | J27: S2
A28: 232 | B28: 2F | C28: 206 | D28: 4#电梯 4#Elevator | E28: 8.3 | F28: N/A | G28: N/A | H28: N/A | I28: N/A | J28: N/A
A29: 232 | B29: 2F | C29: 207 | D29: 楼梯间 Staircase | E29: 23.1 | F29: F17 | G29: W1a | H29: C4 | I29: N/A | J29: S1
A30: 232 | B30: 2F | C30: 208 | D30: 走道 Corridor | E30: 99.8 | F30: F1 | G30: W1a | H30: C4 | I30: N/A | J30: S1
A31: 232 | B31: 2F | D31: 单层建筑面积 | E31: 454.6
A32: 232 | B32: 3F | C32: 301 | D32: 楼梯间 Staircase | E32: 18 | F32: F17 | G32: W1a | H32: C4 | I32: N/A | J32: S1
A33: 232 | B33: 3F | C33: 302 | D33: 前室 Lobby | E33: 11.4 | F33: F1 | G33: W1a | H33: C4 | I33: N/A | J33: S1
A34: 232 | B34: 3F | C34: 303 | D34: 空压机房 Air Compressor Room | E34: 149.9 | F34: F1 | G34: W1a | H34: C4 | I34: N/A | J34: S1
A35: 232 | B35: 3F | C35: 303(A) | D35: 管道井 Shaft | E35: 4 | F35: N/A | G35: N/A | H35: N/A | I35: N/A | J35: N/A
A36: 232 | B36: 3F | C36: 305 | D36: 4#电梯 4#Elevator | E36: 8.3 | F36: N/A | G36: N/A | H36: N/A | I36: N/A | J36: N/A
A37: 232 | B37: 3F | C37: 306 | D37: 楼梯间 Staircase | E37: 17.7 | F37: F17 | G37: W1a | H37: C4 | I37: N/A | J37: S1
A38: 232 | B38: 3F | C38: 307 | D38: 前室 Lobby | E38: 7.3 | F38: F1 | G38: W1a | H38: C4 | I38: N/A | J38: S1
A39: 232 | B39: 3F | D39: 单层建筑面积 | E39: 455.5
A40: 232 | B40: ALL | D40: 总建筑面积 | E40: 1952.6

Sheet 134
H1: ='211'!H1 -> RDSZ Building Room Information
A2: ='211'!A2 -> BUILDIN NO. | B2: ='211'!B2 -> BUILDING FLOOR | C2: ='211'!C2 -> Room-number | D2: ='211'!D2 -> ROOM NAME | E2: ='211'!E2 -> NET AREA | F2: ='211'!F2 -> FLOOR | G2: ='211'!G2 -> WALL | H2: ='211'!H2 -> CEILING | ... O2: ='211'!O2 -> NOTE NO.
A3: ='211'!A3 -> 楼号 | B3: ='211'!B3 -> 楼层 | C3: ='211'!C3 -> 房间号 | D3: ='211'!D3 -> 房间名称 | E3: ='211'!E3 -> 净面积(M2) | F3: ='211'!F3 -> 地面做法 | G3: ='211'!G3 -> 墙面做法 | H3: ='211'!H3 -> 吊顶做法 | ... O3: ='211'!O3 -> 备注索引
A4: 134 | B4: 1F | C4: 101 | D4: 楼梯间一（北） Staircase 1（North） | E4: 17.7
A5: 134 | B5: 1F | C5: 102 | D5: 弱电间 MAF & IDF Room | E5: 15.3
A6: 134 | B6: 1F | C6: 103 | D6: 走道 Corridor | E6: 98.7
A7: 134 | B7: 1F | C7: 105 | D7: 电梯间Elevator | E7: 11.9
A8: 134 | B8: 1F | C8: 106 | D8: 走道 Corridor | E8: 44.8
A9: 134 | B9: 1F | C9: 107 | D9: 办公室 Office | E9: 23.8
A10: 134 | B10: 1F | C10: 108 | D10: 会议室 Meeting RM | E10: 23.2
A11: 134 | B11: 1F | C11: 109 | D11: 会议室 Meeting RM | E11: 22.6
A12: 134 | B12: 1F | C12: 110 | D12: 茶水间 Pantry | E12: 23.8
A13: 134 | B13: 1F | C13: 111 | D13: 打印间兼洗涤室 Printing and Washing | E13: 23.8
A14: 134 | B14: 1F | C14: 112 | D14: 楼梯间二（南） Staircase 2（South） | E14: 15.1
A15: 134 | B15: 1F | C15: 113 | D15: 柴油机房 Diesel Room | E15: 85.5
... A18: 134 | B18: 1F | C18: 123 | D18: 电气控制室 Electrical Control Room | E18: 40.5
A19: 134 | B19: 1F | C19: 125-A | D19: 管道井1 Pipe Shaft 1 | E19: 3.5
A20: 134 | B20: 1F | C20: 126 | D20: 走道 Corridor | E20: 40.5
A21: 134 | B21: 1F | C21: 127 | D21: 女生产更衣间 Female Production Change | E21: 24.8
A22: 134 | B22: 1F | C22: 127-A | D22: 女更衣室 Female Locker Room | E22: 3
A23: 134 | B23: 1F | C23: 128 | D23: 男卫生间 Male Toilet | E23: 17
A24: 134 | B24: 1F | C24: 129 | D24: 女卫生间 Female Toilet | E24: 13
A25: 134 | B25: 1F | C25: 130 | D25: 男生产更衣间 Male Production Change | E25: 24.2
A26: 134 | B26: 1F | C26: 130-A | D26: 男更衣室 Male Locker Room | E26: 3
A27: 134 | B27: 1F | C27: 131 | D27: 会议室 Meeting RM | E27: 24.4
A28: 134 | B28: 1F | C28: 132 | D28: 20KV强电间2 20KV Switch Room2 | E28: 61.3
A29: 134 | B29: 1F | C29: 133 | D29: 20KV强电间1 20KV Switch Room1 | E29: 61.3
A30: 134 | B30: 1F | C30: 135 | D30: 10KV强电间 10KV Switch Room | E30: 97.8
A31: 232 | B31: 1F | D31: 单层建筑面积 | E31: 1088.6
A32: 134 | B32: 2F | C32: 201 | D32: 楼梯间一（北） Staircase 1（North） | E32: 17.7
A33: 134 | B33: 2F | C33: 202 | D33: 电梯Elevator | E33: 11.9
B34: 2F | C34: 203 | D34: 工具间 Tool Room | E34: 74.3
A35: 134 | B35: 2F | C35: 205 | D35: 工作间Workshop | E35: 86
A36: 134 | B36: 2F | C36: 206 | D36: 空调机房 HVAC Room | E36: 58.1
A37: 134 | B37: 2F | C37: 207 | D37: 热水房 Hot Water Room | E37: 53.9
A38: 134 | B38: 2F | C38: 207-A | D38: 排烟风机室 Smoke Fan Room | E38: 18.8
A39: 134 | B39: 2F | C39: 208 | D39: 楼梯间二（南） Staircase 2（South） | E39: 15.1
A40: 134 | B40: 2F | C40: 209 | D40: 存储间 Storage Room | E40: 73
A41: 134 | B41: 2F | C41: 211 | D41: 备件室 Spare Parts Room | E41: 142.8
A42: 134 | B42: 2F | C42: 212 | D42: 技术团队工作间TS Workshop | E42: 173.6
...

Sheet 132
H1: ='211'!H1 -> RDSZ Building Room Information
A2: ='211'!A2 -> BUILDIN NO. | B2: ='211'!B2 -> BUILDING FLOOR | C2: ='211'!C2 -> Room-number | D2: ='211'!D2 -> ROOM NAME | E2: ='211'!E2 -> NET AREA | F2: ='211'!F2 -> FLOOR | G2: ='211'!G2 -> WALL | H2: ='211'!H2 -> CEILING | ... O2: ='211'!O2 -> NOTE NO.
A3: ='211'!A3 -> 楼号 | B3: ='211'!B3 -> 楼层 | C3: ='211'!C3 -> 房间号 | D3: ='211'!D3 -> 房间名称 | E3: ='211'!E3 -> 净面积(M2) | F3: ='211'!F3 -> 地面做法 | G3: ='211'!G3 -> 墙面做法 | H3: ='211'!H3 -> 吊顶做法 | ... O3: ='211'!O3 -> 备注索引
A4: 132 | B4: 1F | C4: 101 | D4: 空调机房 HVAC Room | E4: 20.2
A5: 132 | B5: 1F | C5: 102 | D5: A级储存间 1 Class A(1,2,5,6 item)storage1 | E5: 34.8
A6: 132 | B6: 1F | C6: 103 | D6: A级储存间 2 Class A(1,2,5,6 item)storage2 | E6: 34.8
A7: 132 | B7: 1F | C7: 104 | D7: 甲类毒剂仓库 Class A(1,2,5,6 item)toxic agent storage | E7: 11.2
A8: 132 | B8: 1F | C8: 105 | D8: 前室 Locker | E8: 9.1
A9: 132 | B9: ALL | D9: 总建筑面积 | E9: 128.8

Sheet 111
H1: ='211'!H1 -> RDSZ Building Room Information
A2: ='211'!A2 -> BUILDIN NO. | B2: ='211'!B2 -> BUILDING FLOOR | C2: ='211'!C2 -> Room-number | D2: ='211'!D2 -> ROOM NAME | E2: ='211'!E2 -> NET AREA | F2: ='211'!F2 -> FLOOR | G2: ='211'!G2 -> WALL | H2: ='211'!H2 -> CEILING | ... O2: ='211'!O2 -> NOTE NO.
A3: ='211'!A3 -> 楼号 | B3: ='211'!B3 -> 楼层 | C3: ='211'!C3 -> 房间号 | D3: ='211'!D3 -> 房间名称 | E3: ='211'!E3 -> 净面积(M2) | F3: ='211'!F3 -> 地面做法 | G3: ='211'!G3 -> 墙面做法 | H3: ='211'!H3 -> 吊顶做法 | ... O3: ='211'!O3 -> 备注索引
A4: 111 | B4: 1F | C4: 101 | D4: 咖啡休息室 Cafe Waiting Area | E4: 35.2
A5: 111 | B5: 1F | C5: 102 | D5: 自行车库1 Bicycle Storage 1 | E5: 41.1
A6: 111 | B6: 1F | C6: 103 | D6: 走道 Corridor | E6: 15.7
A7: 111 | B7: 1F | C7: 105 | D7: 机房 Mech. | E7: 14.7
A8: 111 | B8: 1F | C8: 106 | D8: 分析室 Analysis | E8: 13.7
A9: 111 | B9: 1F | C9: 107 | D9: 卫生间 Toilet | E9: 4.4
A10: 111 | B10: 1F | C10: 108 | D10: 保安室 Guard | E10: 12.1
A11: 111 | B11: 1F | C11: 110 | D11: 开闭所 Sub-Section Post | E11: 84
A12: 111 | B12: 1F | C12: 111 | D12: 自行车库2 Bicycle Storage 2 | E12: 256.4
A13: 111 | B13: ALL | D13: 总建筑面积 | E13: 643.8

Sheet 234
H1: ='211'!H1 -> RDSZ Building Room Information
A2: ='211'!A2 -> BUILDIN NO. | B2: ='211'!B2 -> BUILDING FLOOR | C2: ='211'!C2 -> Room-number | D2: ='211'!D2 -> ROOM NAME | E2: ='211'!E2 -> NET AREA | F2: ='211'!F2 -> FLOOR | G2: ='211'!G2 -> WALL | H2: ='211'!H2 -> CEILING | ... O2: ='211'!O2 -> NOTE NO.
A3: ='211'!A3 -> 楼号 | B3: ='211'!B3 -> 楼层 | C3: ='211'!C3 -> 房间号 | D3: ='211'!D3 -> 房间名称 | E3: ='211'!E3 -> 净面积(M2) | F3: ='211'!F3 -> 地面做法 | G3: ='211'!G3 -> 墙面做法 | H3: ='211'!H3 -> 吊顶做法 | ... O3: ='211'!O3 -> 备注索引
A4: 234 | B4: 1F | C4: 101 | D4: 卫生间 Toilet | E4: 4.3
A5: 234 | B5: 1F | C5: 102 | D5: 休息室 Bedroom | E5: 6
A6: 234 | B6: 1F | C6: 103 | D6: 接待区 Good Reception | E6: 13.4
A7: 234 | B7: ALL | D7: 总建筑面积 | E7: 41.5

Sheet 131
H1: ='211'!H1 -> RDSZ Building Room Information
A2: ='211'!A2 -> BUILDIN NO. | B2: ='211'!B2 -> BUILDING FLOOR | C2: ='211'!C2 -> Room-number | D2: ='211'!D2 -> ROOM NAME | E2: ='211'!E2 -> NET AREA | F2: ='211'!F2 -> FLOOR | G2: ='211'!G2 -> WALL | H2: ='211'!H2 -> CEILING | ... O2: ='211'!O2 -> NOTE NO.
A3: ='211'!A3 -> 楼号 | B3: ='211'!B3 -> 楼层 | C3: ='211'!C3 -> 房间号 | D3: ='211'!D3 -> 房间名称 | E3: ='211'!E3 -> 净面积(M2) | F3: ='211'!F3 -> 地面做法 | G3: ='211'!G3 -> 墙面做法 | H3: ='211'!H3 -> 吊顶做法 | ... O3: ='211'!O3 -> 备注索引
A4: 131 | B4: 1F | C4: 101 | D4: 走廊Corridor | E4: 254.4
A5: 131 | B5: 1F | C5: 100 | D5: 收发货间Shipping&Receiving1 | E5: 168.7
A6: 131 | B6: 1F | C6: 102 | D6: 暂存间Staging | E6: 760.5
A7: 131 | B7: 1F | C7: 103 | D7: 废料间Waste | E7: 59.6
A8: 131 | B8: 1F | C8: 104 | D8: 包装车间Pakaging | E8: 1604.8
A9: 131 | B9: 1F | C9: 105 | D9: 更衣室Locker | E9: 31.4
A10: 131 | B10: 1F | C10: 107 | D10: 收发货间2Shipping&Receiving2 | E10: 72.2
A11: 131 | B11: 1F | C11: 108 | D11: 更衣室（男）Gowning(Male) | E11: 22.9
A12: 131 | B12: 1F | C12: 109 | D12: 更衣室（女）Gowning(Female) | E12: 18.4
A13: 131 | B13: 1F | C13: 110 | D13: 人流缓冲间PAL | E13: 5.5
A14: 131 | B14: 1F | C14: 111 | D14: 物流缓冲间MAL2 | E14: 18
A15: 131 | B15: 1F | C15: 112 | D15: 物流缓冲间MAL | E15: 12.2
... A20: 131 | B20: 1F | C20: 117 | D20: 中测间IPC | E20: 7.2
A21: 131 | B21: 1F | C21: 117A | D21: 洁具间2Janitor 2 | E21: 4.5
A22: 131 | B22: 1F | C22: 118 | D22: 清洗间Cleaning | E22: 36.9
A23: 131 | B23: 1F | C23: 119 | D23: 配料间3Charging 3 | E23: 42.3
A24: 131 | B24: 1F | C24: 120 | D24: 洁净走廊Clean Corridor | E24: 167.4
A25: 131 | B25: 1F | C25: 121 | D25: 灌装间1Filling 1 | E25: 96.7
A26: 131 | B26: 1F | C26: 122 | D26: 灌装间2Filling 2 | E26: 107.4
A27: 131 | B27: 1F | C27: 123 | D27: 容器间1Vessel Room 1 | E27: 30.8
A28: 131 | B28: 1F | C28: 124 | D28: 容器间2Vessel Room 2 | E28: 66.9
A29: 131 | B29: 1F | C29: 125 | D29: 预留区走廊Corridor | E29: 36.7
A30: 131 | B30: 1F | C30: 126 | D30: 电气间MCC | E30: 20.1
A31: 131 | B31: 1F | C31: 127 | D31: 纯水间Purified Water | E31: 103.9
A32: 131 | B32: 1F | C32: 128 | D32: 废水处理室Waste Water | E32: 118.6
A33: 131 | B33: 1F | C33: 129 | D33: 容器间3Vessel Room 3 | E33: 47.8
... A37: 131 | B37: 1F | C37: 134 | D37: 氮气储存间N2 Store Room | E37: 2.3
A38: 131 | B38: 1F | C38: S101 | D38: 楼梯间1（北）Stair 1 (North) | E38: 35.3
A39: 131 | B39: 1F | C39: S102 | D39: 楼梯间2（南）Stair 2 (South) | E39: 39.8
A40: 131 | B40: 1F | C40: S103 | D40: 楼梯间3（东南） Stair 3 (Southeast) | E40: 27.7
A41: 131 | B41: 2F | C41: S104 | D41: 楼梯间4（东）Stair 4 (East) | E41: 25.8
A42: 131 | B42: 1F | C42: 一层 | D42: 单层建筑面积 | E42: =SUM(E4:E41) -> 4320.5
A43: 131 | B43: 2F | C43: S201 | D43: 楼梯间1（北）Stair 1 (North) | E43: 35.3
A44: 131 | B44: 2F | C44: 201 | D44: 走廊Corridor | E44: 52.5
A45: 131 | B45: 2F | C45: 202 | D45: 车间Workshops | E45: 344.3
A46: 131 | B46: 2F | C46: 203 | D46: 存储间Store | E46: 9.6
A47: 131 | B47: 2F | C47: 204 | D47: 电气室 Electrical | E47: 12.4
...

Sheet panda
H1: ='211'!H1 -> RDSZ Building Room Information
A2: ='211'!A2 -> BUILDIN NO. | B2: ='211'!B2 -> BUILDING FLOOR | C2: ='211'!C2 -> Room-number | D2: ='211'!D2 -> ROOM NAME | E2: ='211'!E2 -> NET AREA | F2: ='211'!F2 -> FLOOR | G2: ='211'!G2 -> WALL | H2: ='211'!H2 -> CEILING | ... O2: ='211'!O2 -> NOTE NO.
A3: ='211'!A3 -> 楼号 | B3: ='211'!B3 -> 楼层 | C3: ='211'!C3 -> 房间号 | D3: ='211'!D3 -> 房间名称 | E3: ='211'!E3 -> 净面积(M2) | F3: ='211'!F3 -> 地面做法 | G3: ='211'!G3 -> 墙面做法 | H3: ='211'!H3 -> 吊顶做法 | ... O3: ='211'!O3 -> 备注索引
A4: IOA | B4: 1 | C4: 102 | D4: 丙类包装车间（中间站） Class C packaging workshop（transition station） | E4: 613
A5: IOA | B5: 1 | C5: 103 | D5: 组装生产车间（丙二类） Assembly Workshop | E5: 555.7
A6: IOA | B6: 1 | C6: 101 | D6: 中转缓冲区（属于丙类包装车间（中间站））
A7: IOA | B7: 1 | C7: 105 | D7: 走廊 Corridor
A8: IOA | B8: 1 | C8: 106 | D8: 女卫 Toilet
A9: IOA | B9: 1 | C9: 107 | D9: 男卫 Toilet
A10: IOA | B10: 1 | C10: 108 | D10: IT间/监控室 IT Room/Monitoring Room
A11: IOA | B11: 1 | C11: 109 | D11: 会议室 Conference Room
A12: IOA | B12: 1 | C12: 111 | D12: 车间办公室 Office
A13: IOA | B13: 1 | C13: 112 | D13: 门厅 Lobby
A14: IOA | B14: 1 | C14: 113 | D14: 管井 Shaft
A15: IOA | B15: 2 | C15: 03-S02 | D15: 楼梯2 Stair2 | E15: 24.64
C16: 03-S01 | D16: 楼梯1 Stair1 | E16: 16.32
C17: 03-2001 | D17: 办公区 Office | E17: 132.66
C18: 03-2002 | D18: 会议室 Meeting RM1 | E18: 13.76
C19: 03-2003 | D19: 会议准备间 TEL.RM | E19: 6.8
C20: 03-2004 | D20: 会议室2 Meeting RM2 | E20: 32.45
C21: 03-2005 | D21: 茶水间 Rest Room | E21: 22.5
C22: 03-2006 | D22: 文档室 Archive Room | E22: 18.37
C23: 03-2007 | D23: 电话间 TEL.RM 1 | E23: 3.37
C24: 03-2008 | D24: 走道 Corridor | E24: 27.1
C25: 03-2009 | D25: 更衣间 Locker RM | E25: 5.5
C26: 03-2010 | D26: 灭菌间 Sterilization RM | E26: 15.6
C27: 03-2011 | D27: 物料缓冲间 MAL.Buffer | E27: 7.53
... C45: 03-2029 | D45: 准备间 PRE RM | E45: 15.03

Sheet Notes
K1: NOTES
A2: W1a-丙烯酸乳胶漆涂料墙面(实体墙)
A3: W1b丙烯酸乳胶漆涂料墙面(轻质隔墙)
A4: W2瓷砖墙面
A5: W3b无框玻璃隔断
A7: F1a防滑陶瓷地砖 (有防水层）
A8: F2b硬化剂地坪
A9: F3乙烯基地面
A10: F10环氧涂层地面
A11: F11a耐化学品、耐压、耐磨环氧自流平地面
A14: C1轻钢龙骨吸音板吊顶
A15: C2b防水石膏板吊顶
A16: C2c 防火石膏板吊顶
... A23: S5乙烯基踢脚,2.5毫米厚
